<?xml version="1.0" ?>
<!-- =================================================================================== -->
<!-- |    This document was autogenerated by xacro from exabot.xacro                   | -->
<!-- |    EDITING THIS FILE BY HAND IS NOT RECOMMENDED                                 | -->
<!-- =================================================================================== -->
<robot name="exabot" xmlns:xacro="http://ros.org/wiki/xacro">
  <!-- start: including -->
  <!-- end: xacro cylinder inertial -->
  <!-- Defines a cylinder link with the name "'name'_link", a radius
       'radius', a length 'height' and a mass 'mass'. It also defines
       a appropriate 'type' joint with a parent link "'parent'_link" and an
       origin '*origin_joint'. Please remember to set an origin element when
       calling this macro. -->
  <!-- end: xacro cylinder inertial -->
  <!-- end: including -->
  <!-- end: including -->
  <!-- end: parameter definition -->
  <!-- start: world link -->
  <link name="world"/>
  <!-- end: world link -->
  <link name="stand_link">
    <visual>
      <geometry>
        <cylinder length="0.1" radius="0.2"/>
      </geometry>
    </visual>
    <collision>
      <geometry>
        <cylinder length="0.1" radius="0.2"/>
      </geometry>
    </collision>
    <inertial>
      <mass value="100.0"/>
      <origin rpy="0 0 0" xyz="0 0 0"/>
      <inertia ixx="1.08333333333" ixy="0.0" ixz="0.0" iyy="1.08333333333" iyz="0.0" izz="2.0"/>
    </inertial>
  </link>
  <joint name="stand_joint" type="fixed">
    <parent link="world"/>
    <child link="stand_link"/>
    <origin rpy="0 0 0" xyz="0 0 0.05"/>
  </joint>
  <!-- end: stand link/joint -->
  <link name="shoulder_link">
    <visual>
      <geometry>
        <cylinder length="0.4" radius="0.05"/>
      </geometry>
    </visual>
    <collision>
      <geometry>
        <cylinder length="0.4" radius="0.05"/>
      </geometry>
    </collision>
    <inertial>
      <mass value="1.0"/>
      <origin rpy="0 0 0" xyz="0 0 0"/>
      <inertia ixx="0.0139583333333" ixy="0.0" ixz="0.0" iyy="0.0139583333333" iyz="0.0" izz="0.00125"/>
    </inertial>
  </link>
  <joint name="shoulder_joint" type="revolute">
    <parent link="stand_link"/>
    <child link="shoulder_link"/>
    <origin rpy="0 0 0" xyz="0 0 0.25"/>
    <limit effort="30" lower="-1.57079632679" upper="1.57079632679" velocity="1.0"/>
  </joint>
  <!-- end: shoulder link/joint -->
</robot>

