<?xml version="1.0" ?>
<!-- =================================================================================== -->
<!-- |    This document was autogenerated by xacro from ur5_gripper.xacro              | -->
<!-- |    EDITING THIS FILE BY HAND IS NOT RECOMMENDED                                 | -->
<!-- =================================================================================== -->
<robot name="ur5_gripper" xmlns:xacro="http://ros.org/wiki/xacro">
  <link name="gripper_ankle">
    <visual>
      <geometry>
        <box size="0.03 0.2 0.03"/>
      </geometry>
      <origin rpy="0 0 1.57079632679" xyz="0.0 0.0 0.015"/>
    </visual>
    <collision>
      <geometry>
        <box size="0.03 0.2 0.03"/>
      </geometry>
      <origin rpy="0 0 1.57079632679" xyz="0.0 0.0 0.015"/>
    </collision>
    <inertial>
      <mass value="0.1"/>
      <inertia ixx="0.000340833333333" ixy="0.0" ixz="0.0" iyy="1.5e-05" iyz="0.0" izz="0.000340833333333"/>
    </inertial>
  </link>
  <link name="gripper_r_finger">
    <visual>
      <geometry>
        <box size="0.03 0.2 0.03"/>
      </geometry>
      <origin rpy="0 1.57079632679 0" xyz="0.015 0.0 0.0"/>
    </visual>
    <collision>
      <geometry>
        <box size="0.03 0.2 0.03"/>
      </geometry>
      <origin rpy="0 1.57079632679 0" xyz="0.015 0.0 0.0"/>
    </collision>
    <inertial>
      <mass value="0.1"/>
      <inertia ixx="0.000340833333333" ixy="0.0" ixz="0.0" iyy="1.5e-05" iyz="0.0" izz="0.000340833333333"/>
    </inertial>
  </link>
  <joint name="r_finger_joint" type="prismatic">
    <limit effort="100" lower="0" upper="0.07" velocity="0.25"/>
    <dynamics damping="0.1"/>
    <parent link="gripper_ankle"/>
    <child link="gripper_r_finger"/>
    <origin rpy="1.57079632679 0 3.14159265359" xyz="0.0 0.0 0.13"/>
  </joint>
  <link name="gripper_l_finger">
    <visual>
      <geometry>
        <box size="0.03 0.2 0.03"/>
      </geometry>
      <origin rpy="0 0 0" xyz="0.015 0.0 0.0"/>
    </visual>
    <collision>
      <geometry>
        <box size="0.03 0.2 0.03"/>
      </geometry>
      <origin rpy="0 0 0" xyz="0.015 0.0 0.0"/>
    </collision>
    <inertial>
      <mass value="0.1"/>
      <inertia ixx="0.000340833333333" ixy="0.0" ixz="0.0" iyy="1.5e-05" iyz="0.0" izz="0.000340833333333"/>
    </inertial>
  </link>
  <joint name="l_finger_joint" type="prismatic">
    <limit effort="100" lower="0" upper="0.07" velocity="0.25"/>
    <dynamics damping="0.1"/>
    <parent link="gripper_ankle"/>
    <child link="gripper_l_finger"/>
    <origin rpy="1.57079632679 0 0" xyz="0.0 0.0 0.13"/>
  </joint>
  <transmission name="gripper_r_trans">
    <type>transmission_interface/SimpleTransmission</type>
    <joint name="r_finger_joint">
      <hardwareInterface>hardware_interface/EffortJointInterface</hardwareInterface>
    </joint>
    <actuator name="gripper_r_motor">
      <mechanicalReduction>1</mechanicalReduction>
    </actuator>
  </transmission>
  <transmission name="gripper_l_trans">
    <type>transmission_interface/SimpleTransmission</type>
    <joint name="l_finger_joint">
      <hardwareInterface>hardware_interface/EffortJointInterface</hardwareInterface>
    </joint>
    <actuator name="gripper_l_motor">
      <mechanicalReduction>1</mechanicalReduction>
    </actuator>
  </transmission>
  <gazebo>
    <plugin filename="libgazebo_ros_control.so" name="ros_control">
      <!--robotNamespace>/</robotNamespace-->
      <!--robotSimType>gazebo_ros_control/DefaultRobotHWSim</robotSimType-->
    </plugin>
    <!--
    <plugin name="gazebo_ros_power_monitor_controller" filename="libgazebo_ros_power_monitor.so">
      <alwaysOn>true</alwaysOn>
      <updateRate>1.0</updateRate>
      <timeout>5</timeout>
      <powerStateTopic>power_state</powerStateTopic>
      <powerStateRate>10.0</powerStateRate>
      <fullChargeCapacity>87.78</fullChargeCapacity>     
      <dischargeRate>-474</dischargeRate>
      <chargeRate>525</chargeRate>
      <dischargeVoltage>15.52</dischargeVoltage>
      <chargeVoltage>16.41</chargeVoltage>
    </plugin>
-->
  </gazebo>
  <gazebo>
    <plugin filename="libgazebo_ros_joint_state_publisher.so" name="joint_state_publisher">
      <jointName>shoulder_pan_joint, shoulder_lift_joint, elbow_joint, wrist_1_joint, wrist_2_joint, wrist_3_joint, r_finger_joint, l_finger_joint</jointName>
      <updateRate>100</updateRate>
    </plugin>
    <!-- <plugin name="gazebo_mimic_plugin" filename="libroboticsgroup_gazebo_mimic_joint_plugin.so"> -->
    <!--   <joint>r_finger_joint</joint> -->
    <!--   <mimicJoint>l_finger_joint</mimicJoint> -->
    <!--   <multiplier>-1</multiplier> -->
    <!-- </plugin> -->
  </gazebo>
  <gazebo reference="gripper_r_finger">
    <mu1>0.9</mu1>
    <mu2>0.9</mu2>
    <material>Gazebo/Blue</material>
  </gazebo>
  <gazebo reference="gripper_l_finger">
    <mu1>0.9</mu1>
    <mu2>0.9</mu2>
    <material>Gazebo/Red</material>
  </gazebo>
  <gazebo>
    <gripper name="grasping">
      <grasp_check>
        <attach_steps>1</attach_steps>
        <detach_steps>4</detach_steps>
        <min_contact_count>2</min_contact_count>
      </grasp_check>
      <gripper_link>gripper_r_finger</gripper_link>
      <gripper_link>gripper_l_finger</gripper_link>
      <palm_link>gripper_ankle</palm_link>
    </gripper>
  </gazebo>
  <!-- measured from model -->
  <!--property name="shoulder_height" value="0.089159" /-->
  <!--property name="shoulder_offset" value="0.13585" /-->
  <!-- shoulder_offset - elbow_offset + wrist_1_length = 0.10915 -->
  <!--property name="upper_arm_length" value="0.42500" /-->
  <!--property name="elbow_offset" value="0.1197" /-->
  <!-- CAD measured -->
  <!--property name="forearm_length" value="0.39225" /-->
  <!--property name="wrist_1_length" value="0.093" /-->
  <!-- CAD measured -->
  <!--property name="wrist_2_length" value="0.09465" /-->
  <!-- In CAD this distance is 0.930, but in the spec it is 0.09465 -->
  <!--property name="wrist_3_length" value="0.0823" /-->
  <!-- manually measured -->
  <!-- end: including -->
  <!-- end: properties -->
  <link name="base_link">
    <visual>
      <geometry>
        <mesh filename="package://ur_description/meshes/ur5/visual/base.dae"/>
      </geometry>
      <material name="LightGrey">
        <color rgba="0.7 0.7 0.7 1.0"/>
      </material>
    </visual>
    <collision>
      <geometry>
        <mesh filename="package://ur_description/meshes/ur5/collision/base.stl"/>
      </geometry>
    </collision>
    <inertial>
      <mass value="4.0"/>
      <origin rpy="0 0 0" xyz="0.0 0.0 0.0"/>
      <inertia ixx="0.00443333156" ixy="0.0" ixz="0.0" iyy="0.00443333156" iyz="0.0" izz="0.0072"/>
    </inertial>
  </link>
  <joint name="shoulder_pan_joint" type="revolute">
    <parent link="base_link"/>
    <child link="shoulder_link"/>
    <origin rpy="0.0 0.0 0.0" xyz="0.0 0.0 0.089159"/>
    <axis xyz="0 0 1"/>
    <limit effort="150.0" lower="-3.14159265" upper="3.14159265" velocity="3.15"/>
    <dynamics damping="0.0" friction="0.0"/>
  </joint>
  <link name="shoulder_link">
    <visual>
      <geometry>
        <mesh filename="package://ur_description/meshes/ur5/visual/shoulder.dae"/>
      </geometry>
      <material name="LightGrey">
        <color rgba="0.7 0.7 0.7 1.0"/>
      </material>
    </visual>
    <collision>
      <geometry>
        <mesh filename="package://ur_description/meshes/ur5/collision/shoulder.stl"/>
      </geometry>
    </collision>
    <inertial>
      <mass value="3.7"/>
      <origin rpy="0 0 0" xyz="0.0 0.0 0.0"/>
      <inertia ixx="0.010267495893" ixy="0.0" ixz="0.0" iyy="0.010267495893" iyz="0.0" izz="0.00666"/>
    </inertial>
  </link>
  <joint name="shoulder_lift_joint" type="revolute">
    <parent link="shoulder_link"/>
    <child link="upper_arm_link"/>
    <origin rpy="0.0 1.570796325 0.0" xyz="0.0 0.13585 0.0"/>
    <axis xyz="0 1 0"/>
    <limit effort="150.0" lower="-3.14159265" upper="3.14159265" velocity="3.15"/>
    <dynamics damping="0.0" friction="0.0"/>
  </joint>
  <link name="upper_arm_link">
    <visual>
      <geometry>
        <mesh filename="package://ur_description/meshes/ur5/visual/upperarm.dae"/>
      </geometry>
      <material name="LightGrey">
        <color rgba="0.7 0.7 0.7 1.0"/>
      </material>
    </visual>
    <collision>
      <geometry>
        <mesh filename="package://ur_description/meshes/ur5/collision/upperarm.stl"/>
      </geometry>
    </collision>
    <inertial>
      <mass value="8.393"/>
      <origin rpy="0 0 0" xyz="0.0 0.0 0.28"/>
      <inertia ixx="0.22689067591" ixy="0.0" ixz="0.0" iyy="0.22689067591" iyz="0.0" izz="0.0151074"/>
    </inertial>
  </link>
  <joint name="elbow_joint" type="revolute">
    <parent link="upper_arm_link"/>
    <child link="forearm_link"/>
    <origin rpy="0.0 0.0 0.0" xyz="0.0 -0.1197 0.425"/>
    <axis xyz="0 1 0"/>
    <limit effort="150.0" lower="-3.14159265" upper="3.14159265" velocity="3.15"/>
    <dynamics damping="0.0" friction="0.0"/>
  </joint>
  <link name="forearm_link">
    <visual>
      <geometry>
        <mesh filename="package://ur_description/meshes/ur5/visual/forearm.dae"/>
      </geometry>
      <material name="LightGrey">
        <color rgba="0.7 0.7 0.7 1.0"/>
      </material>
    </visual>
    <collision>
      <geometry>
        <mesh filename="package://ur_description/meshes/ur5/collision/forearm.stl"/>
      </geometry>
    </collision>
    <inertial>
      <mass value="2.275"/>
      <origin rpy="0 0 0" xyz="0.0 0.0 0.25"/>
      <inertia ixx="0.049443313556" ixy="0.0" ixz="0.0" iyy="0.049443313556" iyz="0.0" izz="0.004095"/>
    </inertial>
  </link>
  <joint name="wrist_1_joint" type="revolute">
    <parent link="forearm_link"/>
    <child link="wrist_1_link"/>
    <origin rpy="0.0 1.570796325 0.0" xyz="0.0 0.0 0.39225"/>
    <axis xyz="0 1 0"/>
    <limit effort="28.0" lower="-3.14159265" upper="3.14159265" velocity="3.2"/>
    <dynamics damping="0.0" friction="0.0"/>
  </joint>
  <link name="wrist_1_link">
    <visual>
      <geometry>
        <mesh filename="package://ur_description/meshes/ur5/visual/wrist1.dae"/>
      </geometry>
      <material name="LightGrey">
        <color rgba="0.7 0.7 0.7 1.0"/>
      </material>
    </visual>
    <collision>
      <geometry>
        <mesh filename="package://ur_description/meshes/ur5/collision/wrist1.stl"/>
      </geometry>
    </collision>
    <inertial>
      <mass value="1.219"/>
      <origin rpy="0 0 0" xyz="0.0 0.0 0.0"/>
      <inertia ixx="0.111172755531" ixy="0.0" ixz="0.0" iyy="0.111172755531" iyz="0.0" izz="0.21942"/>
    </inertial>
  </link>
  <joint name="wrist_2_joint" type="revolute">
    <parent link="wrist_1_link"/>
    <child link="wrist_2_link"/>
    <origin rpy="0.0 0.0 0.0" xyz="0.0 0.093 0.0"/>
    <axis xyz="0 0 1"/>
    <limit effort="28.0" lower="-3.14159265" upper="3.14159265" velocity="3.2"/>
    <dynamics damping="0.0" friction="0.0"/>
  </joint>
  <link name="wrist_2_link">
    <visual>
      <geometry>
        <mesh filename="package://ur_description/meshes/ur5/visual/wrist2.dae"/>
      </geometry>
      <material name="LightGrey">
        <color rgba="0.7 0.7 0.7 1.0"/>
      </material>
    </visual>
    <collision>
      <geometry>
        <mesh filename="package://ur_description/meshes/ur5/collision/wrist2.stl"/>
      </geometry>
    </collision>
    <inertial>
      <mass value="1.219"/>
      <origin rpy="0 0 0" xyz="0.0 0.0 0.0"/>
      <inertia ixx="0.111172755531" ixy="0.0" ixz="0.0" iyy="0.111172755531" iyz="0.0" izz="0.21942"/>
    </inertial>
  </link>
  <joint name="wrist_3_joint" type="revolute">
    <parent link="wrist_2_link"/>
    <child link="wrist_3_link"/>
    <origin rpy="0.0 0.0 0.0" xyz="0.0 0.0 0.09465"/>
    <axis xyz="0 1 0"/>
    <limit effort="28.0" lower="-3.14159265" upper="3.14159265" velocity="3.2"/>
    <dynamics damping="0.0" friction="0.0"/>
  </joint>
  <link name="wrist_3_link">
    <visual>
      <geometry>
        <mesh filename="package://ur_description/meshes/ur5/visual/wrist3.dae"/>
      </geometry>
      <material name="LightGrey">
        <color rgba="0.7 0.7 0.7 1.0"/>
      </material>
    </visual>
    <collision>
      <geometry>
        <mesh filename="package://ur_description/meshes/ur5/collision/wrist3.stl"/>
      </geometry>
    </collision>
    <inertial>
      <mass value="0.1879"/>
      <origin rpy="0 0 0" xyz="0.0 0.0 0.0"/>
      <inertia ixx="0.0171364731454" ixy="0.0" ixz="0.0" iyy="0.0171364731454" iyz="0.0" izz="0.033822"/>
    </inertial>
  </link>
  <joint name="ee_fixed_joint" type="fixed">
    <parent link="wrist_3_link"/>
    <child link="ee_link"/>
    <origin rpy="0.0 0.0 1.570796325" xyz="0.0 0.0823 0.0"/>
  </joint>
  <link name="ee_link">
    <collision>
      <geometry>
        <box size="0.01 0.01 0.01"/>
      </geometry>
      <origin rpy="0 0 0" xyz="-0.01 0 0"/>
    </collision>
  </link>
  <transmission name="shoulder_pan_trans">
    <type>transmission_interface/SimpleTransmission</type>
    <joint name="shoulder_pan_joint">
      <hardwareInterface>hardware_interface/PositionJointInterface</hardwareInterface>
    </joint>
    <actuator name="shoulder_pan_motor">
      <mechanicalReduction>1</mechanicalReduction>
    </actuator>
  </transmission>
  <transmission name="shoulder_lift_trans">
    <type>transmission_interface/SimpleTransmission</type>
    <joint name="shoulder_lift_joint">
      <hardwareInterface>hardware_interface/PositionJointInterface</hardwareInterface>
    </joint>
    <actuator name="shoulder_lift_motor">
      <mechanicalReduction>1</mechanicalReduction>
    </actuator>
  </transmission>
  <transmission name="elbow_trans">
    <type>transmission_interface/SimpleTransmission</type>
    <joint name="elbow_joint">
      <hardwareInterface>hardware_interface/PositionJointInterface</hardwareInterface>
    </joint>
    <actuator name="elbow_motor">
      <mechanicalReduction>1</mechanicalReduction>
    </actuator>
  </transmission>
  <transmission name="wrist_1_trans">
    <type>transmission_interface/SimpleTransmission</type>
    <joint name="wrist_1_joint">
      <hardwareInterface>hardware_interface/PositionJointInterface</hardwareInterface>
    </joint>
    <actuator name="wrist_1_motor">
      <mechanicalReduction>1</mechanicalReduction>
    </actuator>
  </transmission>
  <transmission name="wrist_2_trans">
    <type>transmission_interface/SimpleTransmission</type>
    <joint name="wrist_2_joint">
      <hardwareInterface>hardware_interface/PositionJointInterface</hardwareInterface>
    </joint>
    <actuator name="wrist_2_motor">
      <mechanicalReduction>1</mechanicalReduction>
    </actuator>
  </transmission>
  <transmission name="wrist_3_trans">
    <type>transmission_interface/SimpleTransmission</type>
    <joint name="wrist_3_joint">
      <hardwareInterface>hardware_interface/PositionJointInterface</hardwareInterface>
    </joint>
    <actuator name="wrist_3_motor">
      <mechanicalReduction>1</mechanicalReduction>
    </actuator>
  </transmission>
  <!-- nothing to do here at the moment -->
  <!-- ROS base_link to UR 'Base' Coordinates transform -->
  <link name="base"/>
  <joint name="base_link-base_fixed_joint" type="fixed">
    <!-- NOTE: this rotation is only needed as long as base_link itself is
                 not corrected wrt the real robot (ie: rotated over 180
                 degrees)
      -->
    <origin rpy="0 0 -3.14159265" xyz="0 0 0"/>
    <parent link="base_link"/>
    <child link="base"/>
  </joint>
  <!-- Frame coincident with all-zeros TCP on UR controller -->
  <link name="tool0"/>
  <joint name="wrist_3_link-tool0_fixed_joint" type="fixed">
    <origin rpy="-1.570796325 0 0" xyz="0 0.0823 0"/>
    <parent link="wrist_3_link"/>
    <child link="tool0"/>
  </joint>
  <!-- gripper instance-->
  <!-- end: compentens instantiating -->
  <!-- end: xacro cylinder inertial -->
  <!-- end: xacro cylinder geometry -->
  <!-- start: world link/joint -->
  <link name="world"/>
  <joint name="world_to_stand" type="fixed">
    <parent link="world"/>
    <child link="stand_link"/>
    <origin rpy="0.0 0.0 0.0" xyz="0.0 0.0 0.55"/>
  </joint>
  <!-- end: world link -->
  <!-- start: base link/joint -->
  <link name="stand_link">
    <visual>
      <geometry>
        <cylinder length="1.1" radius="0.08"/>
      </geometry>
    </visual>
    <collision>
      <geometry>
        <cylinder length="1.1" radius="0.08"/>
      </geometry>
    </collision>
    <inertial>
      <mass value="20.0"/>
      <origin rpy="0 0 0" xyz="0.0 0.0 0.0"/>
      <inertia ixx="2.0486658472" ixy="0.0" ixz="0.0" iyy="2.0486658472" iyz="0.0" izz="0.064"/>
    </inertial>
  </link>
  <joint name="stand_to_robot" type="fixed">
    <parent link="stand_link"/>
    <child link="base_link"/>
    <origin rpy="0.0 0.0 0.0" xyz="0.0 0.0 0.55"/>
  </joint>
  <!-- end: base link -->
  <!-- start: arm-gripper joint -->
  <joint name="to_gripper" type="fixed">
    <parent link="ee_link"/>
    <child link="gripper_ankle"/>
    <origin rpy="-1.57 0 -1.57" xyz="0 0 0"/>
  </joint>
  <!-- end: arm-gripper joint -->
</robot>

